Internal Server Error: /school/registration/
Traceback (most recent call last):
  File "E:\django\usssa\venv\Lib\site-packages\django\db\backends\utils.py", line 105, in _execute
    return self.cursor.execute(sql, params)
           ^^^^^^^^^^^^^^^^^^^^^^^^^^^^^^^^
  File "E:\django\usssa\venv\Lib\site-packages\django\db\backends\mysql\base.py", line 76, in execute
    return self.cursor.execute(query, args)
           ^^^^^^^^^^^^^^^^^^^^^^^^^^^^^^^^
  File "E:\django\usssa\venv\Lib\site-packages\MySQLdb\cursors.py", line 179, in execute
    res = self._query(mogrified_query)
          ^^^^^^^^^^^^^^^^^^^^^^^^^^^^
  File "E:\django\usssa\venv\Lib\site-packages\MySQLdb\cursors.py", line 330, in _query
    db.query(q)
  File "E:\django\usssa\venv\Lib\site-packages\MySQLdb\connections.py", line 261, in query
    _mysql.connection.query(self, query)
MySQLdb.OperationalError: (1054, "Unknown column 'transaction_id' in 'field list'")

The above exception was the direct cause of the following exception:

Traceback (most recent call last):
  File "E:\django\usssa\usssa\school\views.py", line 652, in payment_view
    payment = Payment.objects.create(
              ^^^^^^^^^^^^^^^^^^^^^^^
  File "E:\django\usssa\venv\Lib\site-packages\django\db\models\manager.py", line 87, in manager_method
    return getattr(self.get_queryset(), name)(*args, **kwargs)
           ^^^^^^^^^^^^^^^^^^^^^^^^^^^^^^^^^^^^^^^^^^^^^^^^^^^
  File "E:\django\usssa\venv\Lib\site-packages\django\db\models\query.py", line 679, in create
    obj.save(force_insert=True, using=self.db)
  File "E:\django\usssa\venv\Lib\site-packages\django\db\models\base.py", line 891, in save
    self.save_base(
  File "E:\django\usssa\venv\Lib\site-packages\django\db\models\base.py", line 997, in save_base
    updated = self._save_table(
              ^^^^^^^^^^^^^^^^^
  File "E:\django\usssa\venv\Lib\site-packages\django\db\models\base.py", line 1160, in _save_table
    results = self._do_insert(
              ^^^^^^^^^^^^^^^^
  File "E:\django\usssa\venv\Lib\site-packages\django\db\models\base.py", line 1201, in _do_insert
    return manager._insert(
           ^^^^^^^^^^^^^^^^
  File "E:\django\usssa\venv\Lib\site-packages\django\db\models\manager.py", line 87, in manager_method
    return getattr(self.get_queryset(), name)(*args, **kwargs)
           ^^^^^^^^^^^^^^^^^^^^^^^^^^^^^^^^^^^^^^^^^^^^^^^^^^^
  File "E:\django\usssa\venv\Lib\site-packages\django\db\models\query.py", line 1847, in _insert
    return query.get_compiler(using=using).execute_sql(returning_fields)
           ^^^^^^^^^^^^^^^^^^^^^^^^^^^^^^^^^^^^^^^^^^^^^^^^^^^^^^^^^^^^^
  File "E:\django\usssa\venv\Lib\site-packages\django\db\models\sql\compiler.py", line 1836, in execute_sql
    cursor.execute(sql, params)
  File "E:\django\usssa\venv\Lib\site-packages\django\db\backends\utils.py", line 122, in execute
    return super().execute(sql, params)
           ^^^^^^^^^^^^^^^^^^^^^^^^^^^^
  File "E:\django\usssa\venv\Lib\site-packages\django\db\backends\utils.py", line 79, in execute
    return self._execute_with_wrappers(
           ^^^^^^^^^^^^^^^^^^^^^^^^^^^^
  File "E:\django\usssa\venv\Lib\site-packages\django\db\backends\utils.py", line 92, in _execute_with_wrappers
    return executor(sql, params, many, context)
           ^^^^^^^^^^^^^^^^^^^^^^^^^^^^^^^^^^^^
  File "E:\django\usssa\venv\Lib\site-packages\django\db\backends\utils.py", line 100, in _execute
    with self.db.wrap_database_errors:
  File "E:\django\usssa\venv\Lib\site-packages\django\db\utils.py", line 91, in __exit__
    raise dj_exc_value.with_traceback(traceback) from exc_value
  File "E:\django\usssa\venv\Lib\site-packages\django\db\backends\utils.py", line 105, in _execute
    return self.cursor.execute(sql, params)
           ^^^^^^^^^^^^^^^^^^^^^^^^^^^^^^^^
  File "E:\django\usssa\venv\Lib\site-packages\django\db\backends\mysql\base.py", line 76, in execute
    return self.cursor.execute(query, args)
           ^^^^^^^^^^^^^^^^^^^^^^^^^^^^^^^^
  File "E:\django\usssa\venv\Lib\site-packages\MySQLdb\cursors.py", line 179, in execute
    res = self._query(mogrified_query)
          ^^^^^^^^^^^^^^^^^^^^^^^^^^^^
  File "E:\django\usssa\venv\Lib\site-packages\MySQLdb\cursors.py", line 330, in _query
    db.query(q)
  File "E:\django\usssa\venv\Lib\site-packages\MySQLdb\connections.py", line 261, in query
    _mysql.connection.query(self, query)
django.db.utils.OperationalError: (1054, "Unknown column 'transaction_id' in 'field list'")

During handling of the above exception, another exception occurred:

Traceback (most recent call last):
  File "E:\django\usssa\venv\Lib\site-packages\django\core\handlers\exception.py", line 55, in inner
    response = get_response(request)
               ^^^^^^^^^^^^^^^^^^^^^
  File "E:\django\usssa\venv\Lib\site-packages\django\core\handlers\base.py", line 197, in _get_response
    response = wrapped_callback(request, *callback_args, **callback_kwargs)
               ^^^^^^^^^^^^^^^^^^^^^^^^^^^^^^^^^^^^^^^^^^^^^^^^^^^^^^^^^^^^
  File "E:\django\usssa\usssa\school\views.py", line 665, in payment_view
    print(f"Payment failed for {school}: {str(e)}", exc_info=True)
TypeError: 'exc_info' is an invalid keyword argument for print()
"POST /school/registration/ HTTP/1.1" 500 195219
