Internal Server Error: /
Traceback (most recent call last):
  File "E:\django\usssa\venv\Lib\site-packages\django\utils\module_loading.py", line 30, in import_string
    return cached_import(module_path, class_name)
           ^^^^^^^^^^^^^^^^^^^^^^^^^^^^^^^^^^^^^^
  File "E:\django\usssa\venv\Lib\site-packages\django\utils\module_loading.py", line 16, in cached_import
    return getattr(module, class_name)
           ^^^^^^^^^^^^^^^^^^^^^^^^^^^
AttributeError: module 'accounts.context_processors' has no attribute 'system_status'

The above exception was the direct cause of the following exception:

Traceback (most recent call last):
  File "E:\django\usssa\venv\Lib\site-packages\django\core\handlers\exception.py", line 55, in inner
    response = get_response(request)
               ^^^^^^^^^^^^^^^^^^^^^
  File "E:\django\usssa\venv\Lib\site-packages\django\core\handlers\base.py", line 197, in _get_response
    response = wrapped_callback(request, *callback_args, **callback_kwargs)
               ^^^^^^^^^^^^^^^^^^^^^^^^^^^^^^^^^^^^^^^^^^^^^^^^^^^^^^^^^^^^
  File "E:\django\usssa\usssa\accounts\decorators.py", line 72, in _wrapped_view
    return view_func(request, *args, **kwargs)
           ^^^^^^^^^^^^^^^^^^^^^^^^^^^^^^^^^^^
  File "E:\django\usssa\usssa\accounts\views.py", line 84, in user_login
    return render(request, "auth/login.html", {"form": form})
           ^^^^^^^^^^^^^^^^^^^^^^^^^^^^^^^^^^^^^^^^^^^^^^^^^^
  File "E:\django\usssa\venv\Lib\site-packages\django\shortcuts.py", line 25, in render
    content = loader.render_to_string(template_name, context, request, using=using)
              ^^^^^^^^^^^^^^^^^^^^^^^^^^^^^^^^^^^^^^^^^^^^^^^^^^^^^^^^^^^^^^^^^^^^^
  File "E:\django\usssa\venv\Lib\site-packages\django\template\loader.py", line 62, in render_to_string
    return template.render(context, request)
           ^^^^^^^^^^^^^^^^^^^^^^^^^^^^^^^^^
  File "E:\django\usssa\venv\Lib\site-packages\django\template\backends\django.py", line 107, in render
    return self.template.render(context)
           ^^^^^^^^^^^^^^^^^^^^^^^^^^^^^
  File "E:\django\usssa\venv\Lib\site-packages\django\template\base.py", line 169, in render
    with context.bind_template(self):
  File "C:\Users\DELL\AppData\Local\Programs\Python\Python312\Lib\contextlib.py", line 137, in __enter__
    return next(self.gen)
           ^^^^^^^^^^^^^^
  File "E:\django\usssa\venv\Lib\site-packages\django\template\context.py", line 253, in bind_template
    processors = template.engine.template_context_processors + self._processors
                 ^^^^^^^^^^^^^^^^^^^^^^^^^^^^^^^^^^^^^^^^^^^
  File "E:\django\usssa\venv\Lib\site-packages\django\utils\functional.py", line 47, in __get__
    res = instance.__dict__[self.name] = self.func(instance)
                                         ^^^^^^^^^^^^^^^^^^^
  File "E:\django\usssa\venv\Lib\site-packages\django\template\engine.py", line 118, in template_context_processors
    return tuple(import_string(path) for path in context_processors)
           ^^^^^^^^^^^^^^^^^^^^^^^^^^^^^^^^^^^^^^^^^^^^^^^^^^^^^^^^^
  File "E:\django\usssa\venv\Lib\site-packages\django\template\engine.py", line 118, in <genexpr>
    return tuple(import_string(path) for path in context_processors)
                 ^^^^^^^^^^^^^^^^^^^
  File "E:\django\usssa\venv\Lib\site-packages\django\utils\module_loading.py", line 32, in import_string
    raise ImportError(
ImportError: Module "accounts.context_processors" does not define a "system_status" attribute/class
"GET / HTTP/1.1" 500 129254
